<?xml version="1.0"?>
<robot xmlns:xacro="http://www.ros.org/wiki/xacro"  name="robot">

    <material name="grey">
        <color rgba="0.2 0.2 0.2 1"/>
    </material>

    <material name="white">
        <color rgba="1 1 1 1"/>
    </material>

    <material name="orange">
        <color rgba="1 0.3 0.1 1"/>
    </material>

    <material name="blue">
        <color rgba="0 0 1 1"/>
    </material>


    <link name="world"></link>

    <joint name="world_to_base" type="fixed">
        <parent link="world" />
        <child link="base" />
        <origin  rpy="0 0 0" xyz="0 -1 0" />
        <!--origin  rpy="3.14 0 1.57" xyz="0 -1 0" /-->
    </joint>

    <link name="base">
        <visual>
            <origin xyz="0 0 0" rpy="0 0 0"/>
            <geometry>
                <!--box size="5 0.1 3" /-->
                <box size="0.1 0.1 0.1" />
            </geometry>
            <material name="grey" />
        </visual>
    </link>



    <joint name="shoulder_yaw" type="revolute">
        <parent link="base" />
        <child link="shoulder_yaw_link" />
        <origin  rpy="0 0 0" xyz="1 0 0" />
        <axis rpy="0 0 0" xyz="0 0 1" />
        <limit effort="0.1" lower="-3.1" upper="3.1" velocity="0.2"/>
    </joint>


    <link name="shoulder_yaw_link">
        <visual>
            <origin xyz="0 0 0" rpy="0 0 0"/>
            <geometry>
                <box size="0.01 0.01 0.01" />
            </geometry>
            <material name="orange" />
        </visual>
    </link>
    
    <joint name="shoulder_pitch" type="revolute">
        <parent link="shoulder_yaw_link" />
        <child link="shoulder_pitch_link" />
        <origin  rpy="0 0 0" xyz="0 0 0" />
        <axis rpy="0 0 0" xyz="1 0 0" />
        <limit effort="0.1" lower="-3.1" upper="3.1" velocity="0.2"/>
    </joint>


    <link name="shoulder_pitch_link">
        <visual>
            <origin xyz="0 0 0" rpy="0 0 0"/>
            <geometry>
                <sphere radius=" 0.1" />
            </geometry>
            <material name="grey" />
        </visual>
    </link>
    
    
    <joint name="shoulder_roll" type="revolute">
        <parent link="shoulder_pitch_link" />
        <child link="upper_arm" />
        <origin  rpy="0 0 0" xyz="0 0 0" />
        <axis rpy="0 0 0" xyz="1 0 0" />
        <limit effort="0.1" lower="-3.1" upper="3.1" velocity="0.2"/>
    </joint>


    <link name="upper_arm">
        <visual>
            <origin xyz="0.5 0 0" rpy="0 1.57 0"/>
            <geometry>
                <cylinder length="1" radius="0.06" />
            </geometry>
            <material name="orange" />
        </visual>
    </link>
    

    <joint name="elbow_yaw" type="revolute">
        <parent link="upper_arm" />
        <child link="elbow_yaw_link" />
        <origin  rpy="0 0 0" xyz="1 0 0" />
        <axis rpy="0 0 0" xyz="0 0 1" />
        <limit effort="0.1" lower="-3.1" upper="3.1" velocity="0.2"/>
    </joint>


    <link name="elbow_yaw_link">
        <visual>
            <origin xyz="0 0 0" rpy="0 0 0"/>
            <geometry>
                <box size="0.01 0.01 0.01" />
            </geometry>
            <material name="orange" />
        </visual>
    </link>
    
    <joint name="elbow_pitch" type="revolute">
        <parent link="elbow_yaw_link" />
        <child link="elbow_pitch_link" />
        <origin  rpy="0 0 0" xyz="0 0 0" />
        <axis rpy="0 0 0" xyz="0 1 0" />
        <limit effort="0.1" lower="-3.1" upper="3.1" velocity="0.2"/>
    </joint>


    <link name="elbow_pitch_link">
        <visual>
            <origin xyz="0 0 0" rpy="0 0 0"/>
            <geometry>
                <sphere radius=" 0.1" />
            </geometry>
            <material name="grey" />
        </visual>
    </link>
    
    
    <joint name="elbow_roll" type="revolute">
        <parent link="elbow_pitch_link" />
        <child link="lower_arm" />
        <origin  rpy="0 0 0" xyz="0 0 0" />
        <axis rpy="0 0 0" xyz="1 0 0" />
        <limit effort="0.1" lower="-3.1" upper="3.1" velocity="0.2"/>
    </joint>


    <link name="lower_arm">
        <visual>
            <origin xyz="0.5 0 0" rpy="0 1.57 0"/>
            <geometry>
                <cylinder length="1" radius="0.06" />
            </geometry>
            <material name="orange" />
        </visual>
    </link>

    <!--joint name="shoulder_roll" type="revolute">
        <parent link="base" />
        <child link="shoulder_roll_link" />
        <origin  rpy="0 0 0" xyz="0 2 0" />
        <axis rpy="1 0 0" xyz="0 0 0" />
        <limit effort="0.1" lower="-3.1" upper="3.1" velocity="0.2"/>
    </joint>
    
   
    <link name="shoulder_roll_link">
        <visual>
            <origin xyz="0 0 0" rpy="0 0 0"/>
            <geometry>
                <box size="0.1 0.1 0.1" />
            </geometry>
            <material name="grey" />
        </visual>
    </link-->



    <joint name="world_to_camera" type="fixed">
        <parent link="world" />
        <child link="camera" />
        <origin  rpy="-2 0 2.5" xyz="4 1 2" />
    </joint>
    
    

    <link name="camera">
        <visual>
            <origin xyz="0 0 -0.2"/>
            <geometry>
                <box size="0.2 0.2 0.4" />
            </geometry>
            <material name="blue" />
        </visual>
    </link>


</robot>
